Workbook

Sheet DS
A1: title | B1: magnitude | C1: date_time | D1: cdi | E1: mmi | F1: alert | G1: tsunami | H1: sig | I1: net | J1: nst | K1: dmin | L1: gap | M1: magType | N1: depth | O1: latitude | P1: longitude | Q1: location | R1: continent | S1: country
A2: M 6.5 - 42 km W of Sola, Vanuatu | B2: 6.5 | C2: 45154.533 | D2: 7 | E2: 4 | F2: green | G2: 0 | H2: 657 | I2: us | J2: 114 | K2: 7.177 | L2: 25 | M2: mww | N2: 192.955 | O2: -13.8814 | P2: 167.158 | Q2: Sola, Vanuatu | S2: Vanuatu
A3: M 6.5 - 43 km S of IntipucÃ¡, El Salvador | B3: 6.5 | C3: 45126.015 | D3: 8 | E3: 6 | F3: yellow | G3: 0 | H3: 775 | I3: us | J3: 92 | K3: 0.679 | L3: 40 | M3: mww | N3: 69.727 | O3: 12.814 | P3: -88.1265 | Q3: IntipucÃ¡, El Salvador
A4: M 6.6 - 25 km ESE of LoncopuÃ©, Argentina | B4: 6.6 | C4: 45124.128 | D4: 7 | E4: 5 | F4: green | G4: 0 | H4: 899 | I4: us | J4: 70 | K4: 1.634 | L4: 28 | M4: mww | N4: 171.371 | O4: -38.1911 | P4: -70.3731 | Q4: LoncopuÃ©, Argentina | R4: South America | S4: Argentina
A5: M 7.2 - 98 km S of Sand Point, Alaska | B5: 7.2 | C5: 45123.283 | D5: 6 | E5: 6 | F5: green | G5: 1 | H5: 860 | I5: us | J5: 173 | K5: 0.907 | L5: 36 | M5: mww | N5: 32.571 | O5: 54.3844 | P5: -160.699 | Q5: Sand Point, Alaska
A6: M 7.3 - Alaska Peninsula | B6: 7.3 | C6: 45123.283 | D6: 0 | E6: 5 | G6: 1 | H6: 820 | I6: at | J6: 79 | K6: 0.879451 | L6: 172.8 | M6: Mi | N6: 21 | O6: 54.49 | P6: -160.796 | Q6: Alaska Peninsula
A7: M 6.6 - 277 km NNE of Codrington, Antigua and Barbuda | B7: 6.6 | C7: 45117.853 | D7: 5 | E7: 4 | F7: green | G7: 1 | H7: 802 | I7: us | J7: 95 | K7: 2.454 | L7: 37 | M7: mww | N7: 10 | O7: 20.0196 | P7: -61.0955 | Q7: Codrington, Antigua and Barbuda
A8: M 6.9 - Tonga | B8: 6.9 | C8: 45109.435 | D8: 4 | E8: 4 | F8: green | G8: 1 | H8: 741 | I8: us | J8: 136 | K8: 1.179 | L8: 23 | M8: mww | N8: 229 | O8: -17.853 | P8: -174.937 | Q8: Tonga
A9: M 7.2 - south of the Fiji Islands | B9: 7.2 | C9: 45092.754 | D9: 8 | E9: 6 | F9: green | G9: 1 | H9: 804 | I9: us | J9: 85 | K9: 2.59 | L9: 24 | M9: mww | N9: 167.404 | O9: -22.9824 | P9: -177.208 | Q9: the Fiji Islands
A10: M 6.6 - Panama-Colombia border region | B10: 6.6 | C10: 45071.128 | D10: 6 | E10: 6 | F10: green | G10: 1 | H10: 733 | I10: us | J10: 50 | K10: 2.163 | L10: 129 | M10: mww | N10: 10 | O10: 8.8894 | P10: -77.1231 | Q10: Panama-Colombia border region | S10: Colombia
A11: M 7.1 - southeast of the Loyalty Islands | B11: 7.1 | C11: 45066.077 | D11: 3 | E11: 4 | F11: green | G11: 1 | H11: 777 | I11: us | J11: 98 | K11: 2.812 | L11: 56 | M11: mww | N11: 35.981 | O11: -23.0622 | P11: 170.456 | Q11: the Loyalty Islands
A12: M 7.7 - southeast of the Loyalty Islands | B12: 7.7 | C12: 45065.123 | D12: 5 | E12: 4 | F12: green | G12: 1 | H12: 927 | I12: us | J12: 277 | K12: 3.111 | L12: 15 | M12: mww | N12: 18.027 | O12: -23.2286 | P12: 170.694 | Q12: the Loyalty Islands
A13: M 7.6 - 95 km WNW of Hihifo, Tonga | B13: 7.6 | C13: 45056.668 | D13: 8 | E13: 6 | F13: green | G13: 1 | H13: 907 | I13: us | J13: 111 | K13: 3.631 | L13: 17 | M13: mww | N13: 210.097 | O13: -15.6002 | P13: -174.608 | Q13: Hihifo, Tonga
A14: M 6.6 - south of the Fiji Islands | B14: 6.6 | C14: 45044.134 | D14: 0 | E14: 2 | F14: green | G14: 0 | H14: 670 | I14: us | J14: 52 | K14: 5.123 | L14: 50 | M14: mww | N14: 598.467 | O14: -25.2657 | P14: 178.424 | Q14: the Fiji Islands
A15: M 7.1 - 170 km SSE of Teluk Dalam, Indonesia | B15: 7.1 | C15: 45040.833 | D15: 9 | E15: 7 | F15: green | G15: 0 | H15: 838 | I15: us | J15: 70 | K15: 2.282 | L15: 58 | M15: mww | N15: 15.462 | O15: -0.781 | P15: 98.5339 | Q15: Teluk Dalam, Indonesia | S15: Indonesia
A16: M 7.1 - Kermadec Islands, New Zealand | B16: 7.1 | C16: 45040.028 | D16: 8 | E16: 7 | F16: green | G16: 1 | H16: 777 | I16: us | J16: 126 | K16: 0.708 | L16: 23 | M16: mww | N16: 43.063 | O16: -30.0249 | P16: -177.897 | Q16: Kermadec Islands, New Zealand
A17: M 6.7 - south of the Fiji Islands | B17: 6.7 | C17: 45034.188 | D17: 0 | E17: 3 | F17: green | G17: 1 | H17: 691 | I17: us | J17: 166 | K17: 4.719 | L17: 10 | M17: mww | N17: 595.854 | O17: -22.2844 | P17: 179.391 | Q17: the Fiji Islands
A18: M 7.0 - 96 km N of Tuban, Indonesia | B18: 7 | C18: 45030.413 | D18: 5 | E18: 3 | F18: green | G18: 0 | H18: 818 | I18: us | J18: 131 | K18: 1.881 | L18: 31 | M18: mww | N18: 594.028 | O18: -6.0255 | P18: 112.033 | Q18: Tuban, Indonesia | S18: Indonesia
A19: M 6.5 - near the east coast of the Kamchatka Peninsula, Russia | B19: 6.5 | C19: 45019.129 | D19: 7 | E19: 6 | F19: yellow | G19: 1 | H19: 655 | I19: us | J19: 104 | K19: 0.266 | L19: 30 | M19: mww | N19: 105.631 | O19: 52.7772 | P19: 158.484 | Q19: the Kamchatka Peninsula, Russia | R19: Asia | S19: Russian Federation (the)
A20: M 7.0 - New Guinea, Papua New Guinea | B20: 7 | C20: 45018.753 | D20: 7 | E20: 7 | F20: green | G20: 1 | H20: 781 | I20: us | J20: 105 | K20: 6.45 | L20: 31 | M20: mww | N20: 62.603 | O20: -4.2924 | P20: 143.155 | Q20: New Guinea, Papua New Guinea | R20: Asia | S20: Papua New Guinea
A21: M 6.5 - 84 km NNW of San Antonio de los Cobres, Argentina | B21: 6.5 | C21: 45007.667 | D21: 4 | E21: 4 | F21: green | G21: 0 | H21: 656 | I21: us | J21: 97 | K21: 1.622 | L21: 33 | M21: mww | N21: 209.976 | O21: -23.4797 | P21: -66.5108 | Q21: San Antonio de los Cobres, Argentina | R21: South America | S21: Argentina
A22: M 6.5 - 40 km SSE of Jurm, Afghanistan | B22: 6.5 | C22: 45006.699 | D22: 7 | E22: 5 | F22: green | G22: 0 | H22: 1350 | I22: us | J22: 134 | K22: 2.53 | L22: 13 | M22: mww | N22: 187.589 | O22: 36.5227 | P22: 70.9787 | Q22: Jurm, Afghanistan | R22: Asia | S22: Afghanistan
A23: M 6.8 - near the coast of Ecuador | B23: 6.8 | C23: 45003.717 | D23: 9 | E23: 7 | F23: orange | G23: 1 | H23: 1159 | I23: us | J23: 152 | K23: 0.709 | L23: 28 | M23: mww | N23: 65.842 | O23: -2.851 | P23: -79.8001 | Q23: Ecuador | R23: South America | S23: Ecuador
A24: M 7.0 - Kermadec Islands region | B24: 7 | C24: 45001.039 | D24: 8 | E24: 5 | F24: green | G24: 1 | H24: 756 | I24: us | J24: 116 | K24: 1.789 | L24: 22 | M24: mww | N24: 22.065 | O24: -30.1147 | P24: -176.112 | Q24: Kermadec Islands region
A25: M 6.9 - Kermadec Islands, New Zealand | B25: 6.9 | C25: 44989.278 | D25: 5 | E25: 5 | F25: green | G25: 1 | H25: 735 | I25: us | J25: 108 | K25: 0.784 | L25: 18 | M25: mww | N25: 205.681 | O25: -29.4748 | P25: -178.787 | Q25: Kermadec Islands, New Zealand
A26: M 6.5 - 86 km WSW of Port-Olry, Vanuatu | B26: 6.5 | C26: 44987.753 | D26: 7 | E26: 6 | F26: green | G26: 1 | H26: 653 | I26: us | J26: 66 | K26: 5.483 | L26: 45 | M26: mww | N26: 10 | O26: -15.3597 | P26: 166.385 | Q26: Port-Olry, Vanuatu
A27: M 6.5 - 108 km NW of Kimbe, Papua New Guinea | B27: 6.5 | C27: 44986.233 | D27: 4 | E27: 2 | F27: green | G27: 1 | H27: 652 | I27: us | J27: 115 | K27: 2.739 | L27: 20 | M27: mww | N27: 598.925 | O27: -4.8138 | P27: 149.487 | Q27: Kimbe, Papua New Guinea | S27: Papua New Guinea
A28: M 6.8 - 67 km W of Murghob, Tajikistan | B28: 6.8 | C28: 44980.026 | D28: 9 | E28: 7 | F28: green | G28: 0 | H28: 737 | I28: us | J28: 128 | K28: 1.783 | L28: 20 | M28: mww | N28: 20.522 | O28: 38.0726 | P28: 73.2077 | Q28: Murghob, Tajikistan | R28: Asia | S28: Tajikistan
A29: M 7.5 - 4 km SSE of EkinÃ¶zÃ¼, Turkey | B29: 7.5 | C29: 44963.433 | D29: 9 | E29: 9 | F29: orange | G29: 0 | H29: 1411 | I29: us | J29: 135 | K29: 0.85 | L29: 17 | M29: mww | N29: 10 | O29: 38.0235 | P29: 37.203 | Q29: EkinÃ¶zÃ¼, Turkey | R29: Asia | S29: Turkiye
A30: M 6.7 - 18 km ESE of NurdaÄŸÄ±, Turkey | B30: 6.7 | C30: 44963.061 | D30: 9 | E30: 8 | F30: yellow | G30: 0 | H30: 800 | I30: us | J30: 108 | K30: 0.218 | L30: 44 | M30: mww | N30: 14.497 | O30: 37.4135 | P30: 36.8306 | Q30: NurdaÄŸÄ±, Turkey | R30: Asia | S30: Turkiye
A31: M 7.8 - Central Turkey | B31: 7.8 | C31: 44963.053 | D31: 9 | E31: 9 | F31: red | G31: 0 | H31: 2910 | I31: us | J31: 118 | K31: 1.919 | L31: 32 | M31: mww | N31: 17.925 | O31: 37.2012 | P31: 36.9997 | Q31: Central Turkey | R31: Asia | S31: Turkiye
A32: M 6.8 - | B32: 6.8 | C32: 44946.923 | D32: 4 | E32: 3 | F32: green | G32: 0 | H32: 718 | I32: us | J32: 60 | K32: 5.129 | L32: 61 | M32: mww | N32: 610.671 | O32: -26.7209 | P32: -63.0394 | R32: South America | S32: Argentina
A33: M 7.0 - 153 km NW of Tobelo, Indonesia | B33: 7 | C33: 44944.254 | D33: 3 | E33: 5 | F33: green | G33: 1 | H33: 756 | I33: us | J33: 130 | K33: 1.974 | L33: 17 | M33: mwc | N33: 28.566 | O33: 2.7401 | P33: 127.051 | Q33: Tobelo, Indonesia | S33: Indonesia
A34: M 7.6 - Pulau Pulau Tanimbar, Indonesia | B34: 7.6 | C34: 44935.741 | D34: 5 | E34: 7 | F34: green | G34: 0 | H34: 957 | I34: us | J34: 114 | K34: 1.575 | L34: 21 | M34: mww | N34: 105.249 | O34: -7.0852 | P34: 130.039 | Q34: Pulau Pulau Tanimbar, Indonesia | S34: Indonesia
A35: M 7.0 - Vanuatu | B35: 7 | C35: 44934.522 | D35: 8 | E35: 7 | F35: green | G35: 1 | H35: 768 | I35: us | J35: 116 | K35: 6.096 | L35: 36 | M35: mww | N35: 29 | O35: -14.9383 | P35: 166.878 | Q35: Vanuatu | S35: Vanuatu
A36: M 6.8 - 109 km NE of Hihifo, Tonga | B36: 6.8 | C36: 44899.808 | D36: 5 | E36: 5 | F36: green | G36: 1 | H36: 720 | I36: us | J36: 152 | K36: 2.587 | L36: 26 | M36: mww | N36: 38 | O36: -15.3983 | P36: -172.968 | Q36: Hihifo, Tonga
A37: M 7.0 - 18 km SW of Malango, Solomon Islands | B37: 7 | C37: 44887.085 | D37: 8 | E37: 7 | F37: green | G37: 1 | H37: 768 | I37: us | J37: 117 | K37: 0.509 | L37: 17 | M37: mww | N37: 14 | O37: -9.7963 | P37: 159.596 | Q37: Malango, Solomon Islands | R37: Oceania | S37: Solomon Islands
A38: M 6.9 - 204 km SW of Bengkulu, Indonesia | B38: 6.9 | C38: 44883.567 | D38: 4 | E38: 4 | F38: green | G38: 0 | H38: 735 | I38: us | J38: 99 | K38: 2.229 | L38: 34 | M38: mww | N38: 25 | O38: -4.9559 | P38: 100.738 | Q38: Bengkulu, Indonesia
A39: M 7.0 - | B39: 7 | C39: 44877.298 | D39: 3 | E39: 3 | F39: green | G39: 1 | H39: 755 | I39: us | J39: 147 | K39: 3.125 | L39: 18 | M39: mww | N39: 579 | O39: -20.0508 | P39: -178.346 | R39: Oceania | S39: Fiji
A40: M 7.3 - 205 km ESE of Neiafu, Tonga | B40: 7.3 | C40: 44876.45 | D40: 5 | E40: 5 | F40: green | G40: 1 | H40: 833 | I40: us | J40: 149 | K40: 1.865 | L40: 21 | M40: mww | N40: 37 | O40: -19.2918 | P40: -172.129 | Q40: Neiafu, Tonga
...

Sheet TASK
A1: task1-excel-based exploration
A2: dataset proftile driven entirely by the formulas over the data sheet
A4: dataset | C4: SIZE
A5: number of records | C5: 1000
A6: number of columns | C6: 19
A7: data range start | C7: 34824
A8: data range end | C8: 45154
A10: value range
A11: field | B11: MIN | C11: MAX | D11: AVG | E11: RANGE
A12: magnitude | B12: =MIN(DS!$B$2:$B1001) -> 6.5 | C12: =MAX(DS!$B$2:$B1001) -> 9.1 | D12: =AVERAGE(DS!$B$2:$B1001) -> 6.94015 | E12: =MAX(DS!$B$2:$B1001)-MIN(DS!$B2:$B1001) -> 2.6
A13: Depth | B13: =MIN(DS!$N$2:$N1001) -> 2.7 | C13: =MAX(DS!$N$2:$N1001) -> 670.81 | D13: =AVERAGE(DS!$N$2:$N1001) -> 74.612541 | E13: =MAX(DS!$N$2:$N1001)-MIN(DS!$N2:$N1001) -> 668.11
A14: sig | B14: =MIN(DS!$H$2:$H1001) -> 650 | C14: =MAX(DS!$H$2:$H1001) -> 2910 | D14: =AVERAGE(DS!$H$2:$H1001) -> 847.915 | E14: =MAX(DS!$H$2:$H1001)-MIN(DS!$H2:$H1001) -> 2260
A15: mmi | B15: =MIN(DS!$E$2:$E1001) -> 1 | C15: =MAX(DS!$E$2:$E1001) -> 10 | D15: =AVERAGE(DS!$E$2:$E1001) -> 6.027 | E15: =MAX(DS!$E$2:$E1001)-MIN(DS!$E$2:$E1001) -> 9
A17: COUNT BY MAGNITUDE TYPE (MAG TYPE ,CASE-NORMALISED) | D17: COUNT BY ALERT LEVEL
A18: MAGTYPE | B18: COUNT | D18: ALERT | E18: COUNT
A19: MWW | B19: =COUNTIF(DS!$M$2:$M$1001,"MWW") -> 502 | D19: GREEN | E19: =COUNTIF(DS!$F$2:$F$1001,"GREEN") -> 353
A20: MWC | B20: =COUNTIF(DS!$M$2:$M$1001,"MWC") -> 332 | D20: YELLOW | E20: =COUNTIF(DS!$F$2:$F$1001,"YELLOW") -> 59
A21: MWB | B21: =COUNTIF(DS!$M$2:$M$1001,"MWB") -> 100 | D21: ORANGE | E21: =COUNTIF(DS!$F$2:$F$1001,"ORANGE") -> 24
A22: MB | B22: =COUNTIF(DS!$M$2:$M$1001,"MB") -> 4 | D22: RED | E22: =COUNTIF(DS!$F$2:$F$1001,"RED") -> 13
A23: MW | B23: =COUNTIF(DS!$M$2:$M$1001,"MW") -> 51 | D23: (BLANK/NOT ASSESSED) | E23: =COUNTBLANK(DS!$F$2:$F$1001) -> 551
A24: MS | B24: =COUNTIF(DS!$M$2:$M$1001,"MS") -> 3 | D24: TOTAL | E24: =COUNTIF(DS!$F$2:$F$1001,"GREEN")+COUNTIF(DS!$F$2:$F$1001,"YELLOW")+COUNTIF(DS!$F$2:$F$1001,"ORANGE")+COUNTIF(DS!$F$2:$F$1001,"RED")+COUNTIF(DS!$F$2:$F$1001,"") -> 1000
A25: MD | B25: =COUNTIF(DS!$M$2:$M$1001,"MD") -> 2
A26: ML | B26: =COUNTIF(DS!$M$2:$M$1001,"ML") -> 1
A27: MI | B27: =COUNTIF(DS!$M$2:$M$1001,"MI") -> 5
A28: TOTAL | B28: =COUNTIF(DS!$M$2:$M$1001,"MWW")+COUNTIF(DS!$M$2:$M$1001,"MWC")+COUNTIF(DS!$M$2:$M$1001,"MWB")+COUNTIF(DS!$M$2:$M$1001,"MW")+COUNTIF(DS!$M$2:$M$1001,"MS")+COUNTIF(DS!$M$2:$M$1001,"MD")+COUNTIF(DS!$M$2:$M$1001,"ML")+COUNTIF(DS!$M$2:$M$1001,"MI")+COUNTIF(DS!$M$2:$M$1001,"MB") -> 1000
D29: SIGNIFICANT EARTHQUAKE PER YEAR
A30: MAGNITUDE BAND DISTRIBUTION (CHART SOURCE) | D30: YEARS | E30: COUNT
A31: BAND | B31: COUNT | D31: 1995 | E31: =COUNTIFS(DS!C:C,">="&DATE(1995,1,1),DS!C:C,"<"&DATE(1996,1,1)) -> 29
A32: 6.5-6.9 | B32: =COUNTIFS(DS!$B$2:$B$1001,">=6.5",DS!$B$2:$B$1001,"<=6.9") -> 627 | D32: 1996 | E32: =COUNTIFS(DS!C:C,">="&DATE(1996,1,1),DS!C:C,"<"&DATE(1997,1,1)) -> 35
A33: 7.0-7.4 | B33: =COUNTIFS(DS!$B$2:$B$1001,">=7.0",DS!$B$2:$B$1001,"<=7.4") -> 229 | D33: 1997 | E33: =COUNTIFS(DS!C:C,">="&DATE(1997,1,1),DS!C:C,"<"&DATE(1998,1,1)) -> 28
A34: 7.5-7.9 | B34: =COUNTIFS(DS!$B$2:$B$1001,">=7.5",DS!$B$2:$B$1001,"<=7.9") -> 112 | D34: 1998 | E34: =COUNTIFS(DS!C:C,">="&DATE(1998,1,1),DS!C:C,"<"&DATE(1999,1,1)) -> 23
A35: 8.0-8.4 | B35: =COUNTIFS(DS!$B$2:$B$1001,">=8.0",DS!$B$2:$B$1001,"<=8.4") -> 27 | D35: 1999 | E35: =COUNTIFS(DS!C:C,">="&DATE(1999,1,1),DS!C:C,"<"&DATE(2000,1,1)) -> 33
A36: 8.5-8.9 | B36: =COUNTIFS(DS!$B$2:$B$1001,">=8.5",DS!$B$2:$B$1001,"<=8.9") -> 3 | D36: 2000 | E36: =COUNTIFS(DS!C:C,">="&DATE(2000,1,1),DS!C:C,"<"&DATE(2001,1,1)) -> 35
A37: 9.0-9.4 | B37: =COUNTIFS(DS!$B$2:$B$1001,">=9.0",DS!$B$2:$B$1001,"<=9.4") -> 2 | D37: 2001 | E37: =COUNTIFS(DS!C:C,">="&DATE(2001,1,1),DS!C:C,"<"&DATE(2002,1,1)) -> 28
D38: 2002 | E38: =COUNTIFS(DS!C:C,">="&DATE(2002,1,1),DS!C:C,"<"&DATE(2003,1,1)) -> 25
D39: 2003 | E39: =COUNTIFS(DS!C:C,">="&DATE(2003,1,1),DS!C:C,"<"&DATE(2004,1,1)) -> 31
D40: 2004 | E40: =COUNTIFS(DS!C:C,">="&DATE(2004,1,1),DS!C:C,"<"&DATE(2005,1,1)) -> 32
D41: 2005 | E41: =COUNTIFS(DS!C:C,">="&DATE(2005,1,1),DS!C:C,"<"&DATE(2006,1,1)) -> 28
D42: 2006 | E42: =COUNTIFS(DS!C:C,">="&DATE(2006,1,1),DS!C:C,"<"&DATE(2007,1,1)) -> 26
D43: 2007 | E43: =COUNTIFS(DS!C:C,">="&DATE(2007,1,1),DS!C:C,"<"&DATE(2008,1,1)) -> 37
...
